<?xml version="1.0" ?>

<robot name="a1_motor" xmlns:xacro="http://ros.org/wiki/xacro">

	<link name="world"/>
	<joint name="world_joint" type="fixed">
		<parent link="world"/>
		<child link="base_link"/>
		<origin rpy="0.0 0.0 0.0" xyz="0 0 0.5"/>
	</joint>
	<link name="base_link">
		<visual>
		<origin rpy="0 0 0" xyz="0 0 0"/>
		<geometry>
		<mesh filename="meshes/a1_motor.stl"/>
		</geometry>
  <material name="black">
    <color rgba="0.1 0.1 0.1 1.0"/>
  </material>
		</visual>
		<collision>
		<origin rpy="0 0 0" xyz="0 0.021 0"/>
		<geometry>
		<cylinder length="0.042" radius="0.046"/>
		</geometry>
		</collision>
		<inertial>
		<origin rpy="0 0 0" xyz="0 0 0"/>
		<mass value="0.705"/>
		  <inertia  ixx="0.0006111993117592239" ixy="0" ixz="0" iyy="0.000993951145190498" iyz="0" izz="0.0006111993117592239" />
		</inertial>
	</link>	
	<joint name="joint1" type="revolute">
		<parent link="base_link"/>
		<child link="link1"/>
		<origin rpy="0.0 0.0 0.0" xyz="0 0.03 0"/>
		<axis xyz="0 1 0"/>
                <limit effort="6" lower="-3.05432619099" upper="3.05432619099" velocity="1"/>		
	</joint>
	<link name="link1">
		<visual>
		<origin rpy="0 0 0" xyz="0 0 0"/>
		<geometry>
		<mesh filename="meshes/link1.stl"/>
		</geometry>
  <material name="metal_gray">
    <color rgba="0.5 0.5 0.5 1.0"/>
  </material>
		</visual>
		<collision>
		<origin rpy="0 0 0" xyz="0 0 0"/>
		<geometry>
		<mesh filename="meshes/link1.stl"/>
		</geometry>
		</collision>
		<inertial>
		<origin rpy="0 0 0" xyz="0 0 -0.2"/>
		<mass value="0.705"/>
		  <inertia  ixx="0.0006111993117592239" ixy="0" ixz="0" iyy="0.000993951145190498" iyz="0" izz="0.0006111993117592239" />
		</inertial>
	</link>	
	<joint name="joint2" type="revolute">
		<parent link="link1"/>
		<child link="link2"/>
		<origin rpy="0.0 0.0 0.0" xyz="0 0.0075 -0.2"/>
		<axis xyz="0 1 0"/>
                <limit effort="6" lower="-3.05432619099" upper="3.05432619099" velocity="1"/>			
	</joint>
	<link name="link2">
		<visual>
		<origin rpy="0 0 0" xyz="0 0 0"/>
		<geometry>
		<mesh filename="meshes/link2.stl"/>
		</geometry>
  <material name="metal_gray">
    <color rgba="0.5 0.5 0.5 1.0"/>
  </material>
		</visual>
		<collision>
		<origin rpy="0 0 0" xyz="0 0 0"/>
		<geometry>
		<mesh filename="meshes/link2.stl"/>
		</geometry>
		</collision>
		<inertial>
		<origin rpy="0 0 0" xyz="0 0 -0.2"/>
		<mass value="0.05"/>
		  <inertia  ixx="0.0006111993117592239" ixy="0" ixz="0" iyy="0.000993951145190498" iyz="0" izz="0.0006111993117592239" />
		</inertial>
	</link>

</robot>
